Workbook

Sheet DB
A1: ID | B1: Título | C1: Gênero | D1: Ficção | E1: País | F1: Região | G1: Autor | H1: Ano de Publicação | I1: Séc | J1: Editora | K1: Sexo Autor | L1: Etnia | M1: Autor/Temática LGBTQIA+? | N1: Páginas | O1: Conclusão | P1: Nota
B2: A Droga da Obediência | C2: Infanto-Juvenil | D2: Sim | E2: Brasil | F2: América Latina | G2: Pedro Bandeira | H2: 1984 | I2: =IF(DB!$H2>1000,LEFT(DB!$H2,2)+1,LEFT(DB!$H2,1)+1) -> 20 | J2: Moderna | K2: M | L2: Branca | N2: 191 | O2: 43831 | P2: 3.5
B3: A Droga do Amor | C3: Infanto-Juvenil | D3: Sim | E3: Brasil | F3: América Latina | G3: Pedro Bandeira | H3: 1993 | I3: =IF(DB!$H3>1000,LEFT(DB!$H3,2)+1,LEFT(DB!$H3,1)+1) -> 20 | J3: Moderna | K3: M | L3: Branca | N3: 176 | O3: 43831 | P3: 3.5
B4: A Marca de uma Lágrima | C4: Infanto-Juvenil | D4: Sim | E4: Brasil | F4: América Latina | G4: Pedro Bandeira | H4: 1985 | I4: =IF(DB!$H4>1000,LEFT(DB!$H4,2)+1,LEFT(DB!$H4,1)+1) -> 20 | J4: Moderna | K4: M | L4: Branca | N4: 176 | O4: 43831 | P4: 3.5
B5: As Alegrias da Maternidade | C5: Romance | D5: Sim | E5: Nigéria | F5: África | G5: Buchi Emecheta | H5: 1979 | I5: =IF(DB!$H5>1000,LEFT(DB!$H5,2)+1,LEFT(DB!$H5,1)+1) -> 20 | J5: TAG | K5: F | L5: Negra | N5: 320 | O5: 43831 | P5: 5
B6: A Origem | C6: Romance | D6: Sim | E6: Estados Unidos | F6: América do Norte | G6: Dan Brown | H6: 2017 | I6: =IF(DB!$H6>1000,LEFT(DB!$H6,2)+1,LEFT(DB!$H6,1)+1) -> 21 | J6: Sextante | K6: M | L6: Branca | N6: 432 | O6: 43831 | P6: 4
B7: A Vida, o Universo e Tudo Mais | C7: Infanto-Juvenil | D7: Sim | E7: Reino Unido | F7: Europa | G7: Douglas Adams | H7: 1982 | I7: =IF(DB!$H7>1000,LEFT(DB!$H7,2)+1,LEFT(DB!$H7,1)+1) -> 20 | J7: Arqueiro | K7: M | L7: Branca | N7: 160 | O7: 43831 | P7: 3.5
B8: Fortaleza Digital | C8: Romance | D8: Sim | E8: Estados Unidos | F8: América do Norte | G8: Dan Brown | H8: 1998 | I8: =IF(DB!$H8>1000,LEFT(DB!$H8,2)+1,LEFT(DB!$H8,1)+1) -> 20 | J8: Sextante | K8: M | L8: Branca | N8: 336 | O8: 43831 | P8: 4
B9: A Volta ao Mundo em 80 dias | C9: Romance | D9: Sim | E9: França | F9: Europa | G9: Julio Verne | H9: 1872 | I9: =IF(DB!$H9>1000,LEFT(DB!$H9,2)+1,LEFT(DB!$H9,1)+1) -> 19 | J9: Zahar | K9: M | L9: Branca | N9: 240 | O9: 43831 | P9: 3.5
B10: O Código Da Vinci | C10: Romance | D10: Sim | E10: Estados Unidos | F10: América do Norte | G10: Dan Brown | H10: 2003 | I10: =IF(DB!$H10>1000,LEFT(DB!$H10,2)+1,LEFT(DB!$H10,1)+1) -> 21 | J10: Sextante | K10: M | L10: Branca | N10: 432 | O10: 43831 | P10: 4.5
B11: O Símbolo Perdido | C11: Romance | D11: Sim | E11: Estados Unidos | F11: América do Norte | G11: Dan Brown | H11: 2009 | I11: =IF(DB!$H11>1000,LEFT(DB!$H11,2)+1,LEFT(DB!$H11,1)+1) -> 21 | J11: Sextante | K11: M | L11: Branca | N11: 496 | O11: 43831 | P11: 3
B12: Ponto de Impacto | C12: Romance | D12: Sim | E12: Estados Unidos | F12: América do Norte | G12: Dan Brown | H12: 2001 | I12: =IF(DB!$H12>1000,LEFT(DB!$H12,2)+1,LEFT(DB!$H12,1)+1) -> 21 | J12: Sextante | K12: M | L12: Branca | N12: 448 | O12: 43831 | P12: 4
B13: Inferno | C13: Poesia Épica | D13: Sim | E13: Itália | F13: Europa | G13: Dante Alighieri | H13: 1320 | I13: =IF(DB!$H13>1000,LEFT(DB!$H13,2)+1,LEFT(DB!$H13,1)+1) -> 14 | J13: Nova Fronteira | K13: M | L13: Branca | N13: 176 | O13: 43831 | P13: 3.5
... B38: O Sol é Para Todos | C38: Romance | D38: Sim | E38: Estados Unidos | F38: América do Norte | G38: Harper Lee | H38: 1960 | I38: =IF(DB!$H38>1000,LEFT(DB!$H38,2)+1,LEFT(DB!$H38,1)+1) -> 20 | J38: José Olympio | K38: F | L38: Branca | N38: 350 | O38: 43831 | P38: 3
B39: Odisseia | C39: Poesia Épica | D39: Sim | E39: Grécia | F39: Europa | G39: Homero | H39: -700 | I39: -8 | J39: Nova Fronteira | K39: M | L39: Branca | N39: 424 | O39: 43831 | P39: 4.5
B40: Cama de Gato | C40: Romance | D40: Sim | E40: Estados Unidos | F40: América do Norte | G40: Kurt Vonnegut | H40: 1963 | I40: =IF(DB!$H40>1000,LEFT(DB!$H40,2)+1,LEFT(DB!$H40,1)+1) -> 20 | J40: Aleph | K40: M | L40: Branca | N40: 280 | O40: 43831 | P40: 3.5
B41: Triologia da Fundação | C41: Romance | D41: Sim | E41: Estados Unidos | F41: América do Norte | G41: Isaac Asimov | H41: 1951 | I41: =IF(DB!$H41>1000,LEFT(DB!$H41,2)+1,LEFT(DB!$H41,1)+1) -> 20 | J41: Aleph | K41: M | L41: Branca | N41: 880 | O41: 43831 | P41: 4.5
B42: Harry Potter e a Câmara Secreta | C42: Romance | D42: Sim | E42: Reino Unido | F42: Europa | G42: J. K. Rolling | H42: 1998 | I42: =IF(DB!$H42>1000,LEFT(DB!$H42,2)+1,LEFT(DB!$H42,1)+1) -> 20 | J42: Rocco | K42: F | L42: Branca | N42: 252 | O42: 43831 | P42: 4
B43: Harry Potter e a Ordem da Fênix | C43: Romance | D43: Sim | E43: Reino Unido | F43: Europa | G43: J. K. Rolling | H43: 2003 | I43: =IF(DB!$H43>1000,LEFT(DB!$H43,2)+1,LEFT(DB!$H43,1)+1) -> 21 | J43: Rocco | K43: F | L43: Branca | N43: 704 | O43: 43831 | P43: 3.5
B44: Harry Potter e a Pedra Filosofal | C44: Romance | D44: Sim | E44: Reino Unido | F44: Europa | G44: J. K. Rolling | H44: 1997 | I44: =IF(DB!$H44>1000,LEFT(DB!$H44,2)+1,LEFT(DB!$H44,1)+1) -> 20 | J44: Rocco | K44: F | L44: Branca | N44: 224 | O44: 43831 | P44: 4.5
B45: Harry Potter e As Relíquias da Morte | C45: Romance | D45: Sim | E45: Reino Unido | F45: Europa | G45: J. K. Rolling | H45: 2007 | I45: =IF(DB!$H45>1000,LEFT(DB!$H45,2)+1,LEFT(DB!$H45,1)+1) -> 21 | J45: Rocco | K45: F | L45: Branca | N45: 592 | O45: 43831 | P45: 5
B46: Harry Potter e o Cálice de Fogo | C46: Romance | D46: Sim | E46: Reino Unido | F46: Europa | G46: J. K. Rolling | H46: 2000 | I46: =IF(DB!$H46>1000,LEFT(DB!$H46,2)+1,LEFT(DB!$H46,1)+1) -> 21 | J46: Rocco | K46: F | L46: Branca | N46: 584 | O46: 43831 | P46: 4
B47: Harry Potter e o Enigma do Príncipe | C47: Romance | D47: Sim | E47: Reino Unido | F47: Europa | G47: J. K. Rolling | H47: 2005 | I47: =IF(DB!$H47>1000,LEFT(DB!$H47,2)+1,LEFT(DB!$H47,1)+1) -> 21 | J47: Rocco | K47: F | L47: Branca | N47: 472 | O47: 43831 | P47: 5
B48: Harry Potter e O Prisioneiro de Azkaban | C48: Romance | D48: Sim | E48: Reino Unido | F48: Europa | G48: J. K. Rolling | H48: 1999 | I48: =IF(DB!$H48>1000,LEFT(DB!$H48,2)+1,LEFT(DB!$H48,1)+1) -> 20 | J48: Rocco | K48: F | L48: Branca | N48: 394 | O48: 43831 | P48: 3.5
B49: A Náusea | C49: Filosofia | D49: Sim | E49: França | F49: Europa | G49: Jean-Paul Sartre | H49: 1938 | I49: =IF(DB!$H49>1000,LEFT(DB!$H49,2)+1,LEFT(DB!$H49,1)+1) -> 20 | J49: Nova Fronteira | K49: M | L49: Branca | N49: 204 | O49: 43831 | P49: 5
B50: O Aleph e Outras Histórias | C50: Contos | D50: Sim | E50: Argentina | F50: América Latina | G50: Jorge Luis Borges | H50: 1945 | I50: =IF(DB!$H50>1000,LEFT(DB!$H50,2)+1,LEFT(DB!$H50,1)+1) -> 20 | J50: Companhia das Letras | K50: M | L50: Branca | N50: 160 | O50: 43831 | P50: 4
B51: O Evangelho Segundo Jesus Cristo | C51: Romance | D51: Sim | E51: Portugal | F51: Europa | G51: José Saramago | H51: 1991 | I51: =IF(DB!$H51>1000,LEFT(DB!$H51,2)+1,LEFT(DB!$H51,1)+1) -> 20 | J51: Companhia das Letras | K51: M | L51: Branca | N51: 448 | O51: 43831 | P51: 4.5
... B58: Grandes Gregos | C58: Infanto-Juvenil | D58: Não | E58: Reino Unido | F58: Europa | G58: Terry Deary | H58: 1996 | I58: =IF(DB!$H58>1000,LEFT(DB!$H58,2)+1,LEFT(DB!$H58,1)+1) -> 20 | J58: Melhoramentos | K58: M | L58: Branca | N58: 128 | O58: 43831 | P58: 4
B59: Ilíada | C59: Poesia Épica | D59: Sim | E59: Grécia | F59: Europa | G59: Homero | H59: -700 | I59: -8 | J59: Nova Fronteira | K59: M | L59: Branca | N59: 536 | O59: 43831 | P59: 4.5
B60: Incríveis Incas | C60: Infanto-Juvenil | D60: Não | E60: Reino Unido | F60: Europa | G60: Terry Deary | H60: 2000 | I60: =IF(DB!$H60>1000,LEFT(DB!$H60,2)+1,LEFT(DB!$H60,1)+1) -> 21 | J60: Melhoramentos | K60: M | L60: Branca | N60: 127 | O60: 43831 | P60: 4
B61: Inferno | C61: Romance | D61: Sim | E61: Estados Unidos | F61: América do Norte | G61: Dan Brown | H61: 2013 | I61: =IF(DB!$H61>1000,LEFT(DB!$H61,2)+1,LEFT(DB!$H61,1)+1) -> 21 | J61: Sextante | K61: M | L61: Branca | N61: 448 | O61: 43831 | P61: 4.5
B62: Arthur e a Cidade Proibida | C62: Infanto-Juvenil | D62: Sim | E62: França | F62: Europa | G62: Luc Besson | H62: 2003 | I62: =IF(DB!$H62>1000,LEFT(DB!$H62,2)+1,LEFT(DB!$H62,1)+1) -> 21 | J62: Martins Fontes | K62: M | L62: Branca | N62: 215 | O62: 43831 | P62: 3.5
B63: Arthur e a Guerra dos Dois Mundos | C63: Infanto-Juvenil | D63: Sim | E63: França | F63: Europa | G63: Luc Besson | H63: 2005 | I63: =IF(DB!$H63>1000,LEFT(DB!$H63,2)+1,LEFT(DB!$H63,1)+1) -> 21 | J63: Martins Fontes | K63: M | L63: Branca | N63: 277 | O63: 43831 | P63: 3.5
B64: Arthur e a Vingança de Maltazard | C64: Infanto-Juvenil | D64: Sim | E64: França | F64: Europa | G64: Luc Besson | H64: 2004 | I64: =IF(DB!$H64>1000,LEFT(DB!$H64,2)+1,LEFT(DB!$H64,1)+1) -> 21 | J64: Martins Fontes | K64: M | L64: Branca | N64: 214 | O64: 43831 | P64: 3.5
B65: Arthur e os Minimoys | C65: Infanto-Juvenil | D65: Sim | E65: França | F65: Europa | G65: Luc Besson | H65: 2002 | I65: =IF(DB!$H65>1000,LEFT(DB!$H65,2)+1,LEFT(DB!$H65,1)+1) -> 21 | J65: Martins Fontes | K65: M | L65: Branca | N65: 255 | O65: 43831 | P65: 3.5
B66: Isaac Newton e Sua Maçã | C66: Infanto-Juvenil | D66: Não | E66: Reino Unido | F66: Europa | G66: Kjartan Poskitt | H66: 1999 | I66: =IF(DB!$H66>1000,LEFT(DB!$H66,2)+1,LEFT(DB!$H66,1)+1) -> 20 | J66: Companhia das Letras | K66: M | L66: Branca | N66: 192 | O66: 43831 | P66: 4
B67: Jogos Vorazes | C67: Romance | D67: Sim | E67: Estados Unidos | F67: América do Norte | G67: Suzanne Collins | H67: 2008 | I67: =IF(DB!$H67>1000,LEFT(DB!$H67,2)+1,LEFT(DB!$H67,1)+1) -> 21 | J67: Rocco | K67: F | L67: Branca | N67: 400 | O67: 43831 | P67: 4.5
B68: O Alienista | C68: Contos | D68: Sim | E68: Brasil | F68: América Latina | G68: Machado de Assis | H68: 1882 | I68: =IF(DB!$H68>1000,LEFT(DB!$H68,2)+1,LEFT(DB!$H68,1)+1) -> 19 | J68: Antofágica | K68: M | L68: Negra | N68: 304 | O68: 43831 | P68: 5
B69: Leonardo Da Vinci e Seu Super Cérebro | C69: Infanto-Juvenil | D69: Não | E69: Reino Unido | F69: Europa | G69: Michael Cox | H69: 2000 | I69: =IF(DB!$H69>1000,LEFT(DB!$H69,2)+1,LEFT(DB!$H69,1)+1) -> 21 | J69: Companhia das Letras | K69: M | L69: Branca | N69: 176 | O69: 43831 | P69: 4
B70: O Contos da Aia | C70: Romance | D70: Sim | E70: Canadá | F70: América do Norte | G70: Margaret Atwood | H70: 1985 | I70: =IF(DB!$H70>1000,LEFT(DB!$H70,2)+1,LEFT(DB!$H70,1)+1) -> 20 | J70: Rocco | K70: F | L70: Branca | N70: 368 | O70: 43831 | P70: 3.5
...
